Workbook

Sheet DropList
B1: Processes | J1: CC1 - Awareness of the Citizen's Charter | R1: SQD Rating Scale
B2: Conduct of Training - F2F | J2: 1 | K2: I know what a CC is and I saw this office’s CC. | R2: 5 | S2: Strongly Agree
B3: Conduct of Training - Online | J3: 2 | K3: I know what a CC is but I did NOT see this office’s CC. | R3: 4 | S3: Agree
B4: Consumer Advocacy - F2F | J4: 3 | K4: I learned of the CC only when I saw this office’s CC. | R4: 3 | S4: Neither Agree nor Disagree
B5: Consumer Advocacy - Online | J5: 4 | K5: I do not know what a CC is and I did not see one in this office. | R5: 2 | S5: Disagree
B6: Training and Development - F2F | J6: - | K6: Not Applicable | R6: 1 | S6: Strongly Disagree
B7: Training and Development - Online | R7: - | S7: Not Applicable
J9: CC2 - Visibility of the Citizen's Charter
J10: 1 | K10: Easy to see
J11: 2 | K11: Somewhat easy to see
J12: 3 | K12: Difficult to see
J13: 4 | K13: Not visible
J14: - | K14: Not Applicable
J18: CC3 - Usefulness of the Citizen's Charter
J19: 1 | K19: Helped very much
J20: 2 | K20: Somewhat helped
J21: 3 | K21: Did not helped
J22: - | K22: Not Applicable

Sheet Tabulation Sheet
B2: Customer Satisfaction Feedback - Tabulation Sheet | Q2: Document Code: | R2: FM-CSF-ACT-TAB
B3: Office: | C3: =Report!A7 -> [Bureau/Office] | Q3: Version No.: | R3: 0
B4: Process: | C4: =Report!B10 -> 0 | Q4: Effectivity Date: | R4: September 1, 2025
B5: Period: | C5: =Report!A8 -> For the period [Month, DD, YYYY]
B8: No. | C8: Name/Codename | D8: Age Group | E8: Sex | F8: Client Type | G8: CC1 | H8: CC2 | I8: CC3 | J8: Overall Rating/SQD 0 | K8: Responsiveness | L8: Reliability | M8: Access and Facilities | N8: Communication | O8: Costs | P8: Integrity | Q8: Assurance | R8: Outcome
B9: 1 | C9: Client 1 | D9: 20-34 | E9: M | F9: Citizen | G9: 1 | H9: 1 | I9: 1 | J9: 5 | K9: 5 | L9: 5 | M9: 5 | N9: 4 | O9: - | P9: 4 | Q9: 5 | R9: 4
B10: 2 | C10: Client 2 | D10: 19 or lower | E10: F | F10: Business | G10: 1 | H10: 1 | I10: 1 | J10: 5 | K10: 5 | L10: 5 | M10: 5 | N10: 4 | O10: - | P10: 4 | Q10: 5 | R10: 4
B11: 3 | C11: Client 3 | D11: 50-64 | E11: M | F11: Citizen | G11: 1 | H11: 1 | I11: 1 | J11: 5 | K11: 5 | L11: 5 | M11: 5 | N11: 4 | O11: - | P11: 4 | Q11: 5 | R11: 4
B12: 4 | C12: Client 4 | D12: 20-34 | E12: M | F12: Business | G12: 1 | H12: 1 | I12: 1 | J12: 5 | K12: 5 | L12: 5 | M12: 5 | N12: 4 | O12: - | P12: 4 | Q12: 5 | R12: 4
B13: 5 | C13: Client 5 | D13: 20-34 | E13: M | F13: Citizen | G13: 1 | H13: 1 | I13: 1 | J13: 5 | K13: 5 | L13: 5 | M13: 5 | N13: 4 | O13: - | P13: 4 | Q13: 5 | R13: 4
B14: 6 | C14: Client 6 | D14: 50-64 | E14: M | F14: Business | G14: 1 | H14: 1 | I14: 1 | J14: 5 | K14: 5 | L14: 5 | M14: 5 | N14: 4 | O14: - | P14: 4 | Q14: 5 | R14: 4
B15: 7 | C15: Client 7 | D15: 50-64 | E15: F | F15: Business | G15: 1 | H15: 3 | I15: 1 | J15: 5 | K15: 5 | L15: 5 | M15: 5 | N15: 4 | O15: - | P15: 4 | Q15: 5 | R15: 4
B16: 8 | C16: Client 8 | D16: 35-49 | E16: F | F16: Business | G16: 1 | H16: 1 | I16: 1 | J16: 5 | K16: 5 | L16: 5 | M16: 5 | N16: 4 | O16: - | P16: 4 | Q16: 5 | R16: 4
B17: 9 | C17: Client 9 | D17: 20-34 | E17: F | F17: Government | G17: 1 | H17: 1 | I17: 1 | J17: 5 | K17: 5 | L17: 5 | M17: 5 | N17: 4 | O17: - | P17: 4 | Q17: 5 | R17: 4
B18: 10 | C18: Client 10 | D18: 35-49 | E18: M | F18: Business | G18: 1 | H18: 1 | I18: 1 | J18: 5 | K18: 5 | L18: 5 | M18: 5 | N18: 4 | O18: - | P18: 4 | Q18: 5 | R18: 4
B19: 11 | C19: Client 11 | D19: 35-49 | E19: M | F19: Business | G19: 1 | H19: 1 | I19: 1 | J19: 5 | K19: 5 | L19: 5 | M19: 5 | N19: 4 | O19: - | P19: 4 | Q19: 5 | R19: 4
B20: 12 | C20: Client 12 | D20: Did not specify | E20: Did not specify | F20: Did not specify | G20: - | H20: - | I20: - | J20: - | K20: - | L20: - | M20: - | N20: - | O20: - | P20: - | Q20: - | R20: -
B21: 13 | C21: Client 13 | D21: 20-34 | E21: F | F21: Citizen | G21: 1 | H21: 1 | I21: 1 | J21: 5 | K21: 5 | L21: 5 | M21: 5 | N21: 3 | O21: - | P21: 3 | Q21: 5 | R21: 4
B22: 14 | C22: Client 14 | D22: 20-34 | E22: M | F22: Business | G22: 1 | H22: 1 | I22: 1 | J22: 5 | K22: 5 | L22: 5 | M22: 5 | N22: 4 | O22: - | P22: 4 | Q22: 5 | R22: 4
B23: 15 | C23: Client 15 | D23: 19 or lower | E23: F | F23: Citizen | G23: 1 | H23: 1 | I23: 1 | J23: 5 | K23: 2 | L23: 5 | M23: 5 | N23: 4 | O23: - | P23: 4 | Q23: 5 | R23: 4
B24: 16 | C24: Client 16 | D24: 50-64 | E24: F | F24: Government | G24: 1 | H24: 1 | I24: 1 | J24: 5 | K24: 5 | L24: 5 | M24: 5 | N24: 4 | O24: - | P24: 4 | Q24: 5 | R24: 4
B25: 17 | C25: Client 17 | D25: 20-34 | E25: M | F25: Business | G25: 1 | H25: 1 | I25: 1 | J25: 5 | K25: 5 | L25: 5 | M25: 5 | N25: 4 | O25: - | P25: 4 | Q25: 5 | R25: 4
B26: 18 | C26: Client 18 | D26: 20-34 | E26: M | F26: Business | G26: 1 | H26: 1 | I26: 1 | J26: 5 | K26: 5 | L26: 4 | M26: 5 | N26: 4 | O26: - | P26: 4 | Q26: 5 | R26: 4
B27: 19 | C27: Client 19 | D27: 20-34 | E27: F | F27: Government | G27: 1 | H27: 1 | I27: 1 | J27: 5 | K27: 5 | L27: 4 | M27: 5 | N27: 4 | O27: - | P27: 4 | Q27: 5 | R27: 4
B28: 20 | C28: Client 20 | D28: 20-34 | E28: M | F28: Business | G28: 1 | H28: 1 | I28: 1 | J28: 5 | K28: 5 | L28: 4 | M28: 5 | N28: 4 | O28: - | P28: 4 | Q28: 5 | R28: 4
B29: 21 | C29: Client 21 | D29: 50-64 | E29: M | F29: Government | G29: 1 | H29: 1 | I29: 1 | J29: 5 | K29: 5 | L29: 4 | M29: 5 | N29: 5 | O29: - | P29: 4 | Q29: 5 | R29: 4
B30: 22 | C30: Client 22 | D30: 35-49 | E30: M | F30: Citizen | G30: 1 | H30: 1 | I30: 1 | J30: 5 | K30: 5 | L30: 4 | M30: 5 | N30: 5 | O30: - | P30: 4 | Q30: 5 | R30: 4
B31: 23 | C31: Client 23 | D31: 35-49 | E31: M | F31: Business | G31: 1 | H31: 1 | I31: 1 | J31: 5 | K31: 5 | L31: 3 | M31: 5 | N31: 5 | O31: - | P31: 4 | Q31: 5 | R31: 4
B32: 24 | C32: Client 24 | D32: 20-34 | E32: M | F32: Business | G32: 1 | H32: 1 | I32: 1 | J32: 5 | K32: 5 | L32: 3 | M32: 5 | N32: 5 | O32: - | P32: 4 | Q32: 5 | R32: 4
... B39: 31 | C39: Client 31 | D39: 20-34 | E39: F | F39: Government | G39: 1 | H39: 1 | I39: 1 | J39: 5 | K39: 5 | L39: 3 | M39: 5 | N39: 5 | O39: - | P39: 3 | Q39: 5 | R39: 4

Sheet Supplemental
B2: Customer Satisfaction Feedback - Tabulation Sheet
B3: Office: | C3: =Report!A7 -> [Bureau/Office]
B4: Process: | C4: =Report!B10 -> 0
B5: Period: | C5: =Report!A8 -> For the period [Month, DD, YYYY]
B8: No. | C8: Name/Codename | D8: Age Group | E8: Sex | F8: Client Type | G8: Speaker 1 | H8: Speaker 2 | I8: Speaker 3 | J8: Speaker 4 | K8: Speaker 5 | L8: Speaker 6 | M8: Speaker 7 | N8: Speaker 8
B9: ='Tabulation Sheet'!B9 -> 1 | C9: ='Tabulation Sheet'!C9 -> Client 1 | D9: ='Tabulation Sheet'!D9 -> 20-34 | E9: ='Tabulation Sheet'!E9 -> M | F9: ='Tabulation Sheet'!F9 -> Citizen | G9: 4 | H9: 5 | I9: 5 | J9: 5 | K9: 5 | L9: 4 | M9: 4 | N9: 4
B10: ='Tabulation Sheet'!B10 -> 2 | C10: ='Tabulation Sheet'!C10 -> Client 2 | D10: ='Tabulation Sheet'!D10 -> 19 or lower | E10: ='Tabulation Sheet'!E10 -> F | F10: ='Tabulation Sheet'!F10 -> Business | G10: 4 | H10: 5 | I10: 5 | J10: 5 | K10: 5 | L10: 4 | M10: 4 | N10: 4
B11: ='Tabulation Sheet'!B11 -> 3 | C11: ='Tabulation Sheet'!C11 -> Client 3 | D11: ='Tabulation Sheet'!D11 -> 50-64 | E11: ='Tabulation Sheet'!E11 -> M | F11: ='Tabulation Sheet'!F11 -> Citizen | G11: 4 | H11: 5 | I11: 5 | J11: 5 | K11: 5 | L11: 4 | M11: 4 | N11: 4
B12: ='Tabulation Sheet'!B12 -> 4 | C12: ='Tabulation Sheet'!C12 -> Client 4 | D12: ='Tabulation Sheet'!D12 -> 20-34 | E12: ='Tabulation Sheet'!E12 -> M | F12: ='Tabulation Sheet'!F12 -> Business | G12: 4 | H12: 5 | I12: 5 | J12: 5 | K12: 5 | L12: 4 | M12: 4 | N12: 4
B13: ='Tabulation Sheet'!B13 -> 5 | C13: ='Tabulation Sheet'!C13 -> Client 5 | D13: ='Tabulation Sheet'!D13 -> 20-34 | E13: ='Tabulation Sheet'!E13 -> M | F13: ='Tabulation Sheet'!F13 -> Citizen | G13: 5 | H13: 5 | I13: 5 | J13: 5 | K13: 5 | L13: 5 | M13: 5 | N13: 5
B14: ='Tabulation Sheet'!B14 -> 6 | C14: ='Tabulation Sheet'!C14 -> Client 6 | D14: ='Tabulation Sheet'!D14 -> 50-64 | E14: ='Tabulation Sheet'!E14 -> M | F14: ='Tabulation Sheet'!F14 -> Business | G14: 4 | H14: 5 | I14: 5 | J14: 5 | K14: 5 | L14: 5 | M14: 5 | N14: 5
B15: ='Tabulation Sheet'!B15 -> 7 | C15: ='Tabulation Sheet'!C15 -> Client 7 | D15: ='Tabulation Sheet'!D15 -> 50-64 | E15: ='Tabulation Sheet'!E15 -> F | F15: ='Tabulation Sheet'!F15 -> Business | G15: 4 | H15: 5 | I15: 5 | J15: 5 | K15: 5 | L15: 5 | M15: 5 | N15: 5
B16: ='Tabulation Sheet'!B16 -> 8 | C16: ='Tabulation Sheet'!C16 -> Client 8 | D16: ='Tabulation Sheet'!D16 -> 35-49 | E16: ='Tabulation Sheet'!E16 -> F | F16: ='Tabulation Sheet'!F16 -> Business | G16: 4 | H16: 5 | I16: 5 | J16: 5 | K16: 5 | L16: 5 | M16: 5 | N16: 5
B17: ='Tabulation Sheet'!B17 -> 9 | C17: ='Tabulation Sheet'!C17 -> Client 9 | D17: ='Tabulation Sheet'!D17 -> 20-34 | E17: ='Tabulation Sheet'!E17 -> F | F17: ='Tabulation Sheet'!F17 -> Government | G17: 4 | H17: 5 | I17: 5 | J17: 5 | K17: 5 | L17: 5 | M17: 5 | N17: 5
B18: ='Tabulation Sheet'!B18 -> 10 | C18: ='Tabulation Sheet'!C18 -> Client 10 | D18: ='Tabulation Sheet'!D18 -> 35-49 | E18: ='Tabulation Sheet'!E18 -> M | F18: ='Tabulation Sheet'!F18 -> Business | G18: 4 | H18: 5 | I18: 5 | J18: 5 | K18: 5 | L18: 5 | M18: 5 | N18: 5
B19: ='Tabulation Sheet'!B19 -> 11 | C19: ='Tabulation Sheet'!C19 -> Client 11 | D19: ='Tabulation Sheet'!D19 -> 35-49 | E19: ='Tabulation Sheet'!E19 -> M | F19: ='Tabulation Sheet'!F19 -> Business | G19: 4 | H19: 5 | I19: 5 | J19: 5 | K19: 5 | L19: 4 | M19: 4 | N19: 4
B20: ='Tabulation Sheet'!B20 -> 12 | C20: ='Tabulation Sheet'!C20 -> Client 12 | D20: ='Tabulation Sheet'!D20 -> Did not specify | E20: ='Tabulation Sheet'!E20 -> Did not specify | F20: ='Tabulation Sheet'!F20 -> Did not specify | G20: - | H20: 5 | I20: 5 | J20: 5 | K20: 5 | L20: 4 | M20: 4 | N20: 4
B21: ='Tabulation Sheet'!B21 -> 13 | C21: ='Tabulation Sheet'!C21 -> Client 13 | D21: ='Tabulation Sheet'!D21 -> 20-34 | E21: ='Tabulation Sheet'!E21 -> F | F21: ='Tabulation Sheet'!F21 -> Citizen | G21: 4 | H21: 5 | I21: 5 | J21: 5 | K21: 5 | L21: 4 | M21: 4 | N21: 4
B22: ='Tabulation Sheet'!B22 -> 14 | C22: ='Tabulation Sheet'!C22 -> Client 14 | D22: ='Tabulation Sheet'!D22 -> 20-34 | E22: ='Tabulation Sheet'!E22 -> M | F22: ='Tabulation Sheet'!F22 -> Business | G22: 4 | H22: 5 | I22: 5 | J22: 5 | K22: 5 | L22: 4 | M22: 4 | N22: 4
B23: ='Tabulation Sheet'!B23 -> 15 | C23: ='Tabulation Sheet'!C23 -> Client 15 | D23: ='Tabulation Sheet'!D23 -> 19 or lower | E23: ='Tabulation Sheet'!E23 -> F | F23: ='Tabulation Sheet'!F23 -> Citizen | G23: 4 | H23: 5 | I23: 5 | J23: 5 | K23: 5 | L23: 4 | M23: 4 | N23: 4
B24: ='Tabulation Sheet'!B24 -> 16 | C24: ='Tabulation Sheet'!C24 -> Client 16 | D24: ='Tabulation Sheet'!D24 -> 50-64 | E24: ='Tabulation Sheet'!E24 -> F | F24: ='Tabulation Sheet'!F24 -> Government | G24: 4 | H24: 5 | I24: 5 | J24: 5 | K24: 5 | L24: 4 | M24: 4 | N24: 4
B25: ='Tabulation Sheet'!B25 -> 17 | C25: ='Tabulation Sheet'!C25 -> Client 17 | D25: ='Tabulation Sheet'!D25 -> 20-34 | E25: ='Tabulation Sheet'!E25 -> M | F25: ='Tabulation Sheet'!F25 -> Business | G25: 4 | H25: 5 | I25: 5 | J25: 5 | K25: 5 | L25: 5 | M25: 5 | N25: 5
B26: ='Tabulation Sheet'!B26 -> 18 | C26: ='Tabulation Sheet'!C26 -> Client 18 | D26: ='Tabulation Sheet'!D26 -> 20-34 | E26: ='Tabulation Sheet'!E26 -> M | F26: ='Tabulation Sheet'!F26 -> Business | G26: 4 | H26: 5 | I26: 5 | J26: 5 | K26: 5 | L26: 5 | M26: 5 | N26: 5
B27: ='Tabulation Sheet'!B27 -> 19 | C27: ='Tabulation Sheet'!C27 -> Client 19 | D27: ='Tabulation Sheet'!D27 -> 20-34 | E27: ='Tabulation Sheet'!E27 -> F | F27: ='Tabulation Sheet'!F27 -> Government | G27: 4 | H27: 5 | I27: 5 | J27: 5 | K27: 5 | L27: 5 | M27: 5 | N27: 5
B28: ='Tabulation Sheet'!B28 -> 20 | C28: ='Tabulation Sheet'!C28 -> Client 20 | D28: ='Tabulation Sheet'!D28 -> 20-34 | E28: ='Tabulation Sheet'!E28 -> M | F28: ='Tabulation Sheet'!F28 -> Business | G28: 4 | H28: 5 | I28: 5 | J28: 5 | K28: 5 | L28: 5 | M28: 5 | N28: 5
B29: ='Tabulation Sheet'!B29 -> 21 | C29: ='Tabulation Sheet'!C29 -> Client 21 | D29: ='Tabulation Sheet'!D29 -> 50-64 | E29: ='Tabulation Sheet'!E29 -> M | F29: ='Tabulation Sheet'!F29 -> Government | G29: 4 | H29: 5 | I29: 5 | J29: 5 | K29: 5 | L29: 5 | M29: 5 | N29: 5
B30: ='Tabulation Sheet'!B30 -> 22 | C30: ='Tabulation Sheet'!C30 -> Client 22 | D30: ='Tabulation Sheet'!D30 -> 35-49 | E30: ='Tabulation Sheet'!E30 -> M | F30: ='Tabulation Sheet'!F30 -> Citizen | G30: 4 | H30: 5 | I30: 5 | J30: 5 | K30: 5 | L30: 5 | M30: 5 | N30: 5
B31: ='Tabulation Sheet'!B31 -> 23 | C31: ='Tabulation Sheet'!C31 -> Client 23 | D31: ='Tabulation Sheet'!D31 -> 35-49 | E31: ='Tabulation Sheet'!E31 -> M | F31: ='Tabulation Sheet'!F31 -> Business | G31: 4 | H31: 5 | I31: 5 | J31: 5 | K31: 5 | L31: 5 | M31: 5 | N31: 5
B32: ='Tabulation Sheet'!B32 -> 24 | C32: ='Tabulation Sheet'!C32 -> Client 24 | D32: ='Tabulation Sheet'!D32 -> 20-34 | E32: ='Tabulation Sheet'!E32 -> M | F32: ='Tabulation Sheet'!F32 -> Business | G32: 4 | H32: 5 | I32: 5 | J32: 5 | K32: 5 | L32: 5 | M32: 5 | N32: 5
... B39: ='Tabulation Sheet'!B39 -> 31 | C39: ='Tabulation Sheet'!C39 -> Client 31 | D39: ='Tabulation Sheet'!D39 -> 20-34 | E39: ='Tabulation Sheet'!E39 -> F | F39: ='Tabulation Sheet'!F39 -> Government | G39: 5 | H39: 5 | I39: 5 | J39: 5 | K39: 5 | L39: 5 | M39: 5 | N39: 5
B40: ='Tabulation Sheet'!B40 -> 0 | C40: ='Tabulation Sheet'!C40 -> 0 | D40: ='Tabulation Sheet'!D40 -> 0 | E40: ='Tabulation Sheet'!E40 -> 0 | F40: ='Tabulation Sheet'!F40 -> 0
B41: ='Tabulation Sheet'!B41 -> 0 | C41: ='Tabulation Sheet'!C41 -> 0 | D41: ='Tabulation Sheet'!D41 -> 0 | E41: ='Tabulation Sheet'!E41 -> 0 | F41: ='Tabulation Sheet'!F41 -> 0
B42: ='Tabulation Sheet'!B42 -> 0 | C42: ='Tabulation Sheet'!C42 -> 0 | D42: ='Tabulation Sheet'!D42 -> 0 | E42: ='Tabulation Sheet'!E42 -> 0 | F42: ='Tabulation Sheet'!F42 -> 0
B43: ='Tabulation Sheet'!B43 -> 0 | C43: ='Tabulation Sheet'!C43 -> 0 | D43: ='Tabulation Sheet'!D43 -> 0 | E43: ='Tabulation Sheet'!E43 -> 0 | F43: ='Tabulation Sheet'!F43 -> 0
B44: ='Tabulation Sheet'!B44 -> 0 | C44: ='Tabulation Sheet'!C44 -> 0 | D44: ='Tabulation Sheet'!D44 -> 0 | E44: ='Tabulation Sheet'!E44 -> 0 | F44: ='Tabulation Sheet'!F44 -> 0
B45: ='Tabulation Sheet'!B45 -> 0 | C45: ='Tabulation Sheet'!C45 -> 0 | D45: ='Tabulation Sheet'!D45 -> 0 | E45: ='Tabulation Sheet'!E45 -> 0 | F45: ='Tabulation Sheet'!F45 -> 0
B46: ='Tabulation Sheet'!B46 -> 0 | C46: ='Tabulation Sheet'!C46 -> 0 | D46: ='Tabulation Sheet'!D46 -> 0 | E46: ='Tabulation Sheet'!E46 -> 0 | F46: ='Tabulation Sheet'!F46 -> 0
B47: ='Tabulation Sheet'!B47 -> 0 | C47: ='Tabulation Sheet'!C47 -> 0 | D47: ='Tabulation Sheet'!D47 -> 0 | E47: ='Tabulation Sheet'!E47 -> 0 | F47: ='Tabulation Sheet'!F47 -> 0
B48: ='Tabulation Sheet'!B48 -> 0 | C48: ='Tabulation Sheet'!C48 -> 0 | D48: ='Tabulation Sheet'!D48 -> 0 | E48: ='Tabulation Sheet'!E48 -> 0 | F48: ='Tabulation Sheet'!F48 -> 0
B49: ='Tabulation Sheet'!B49 -> 0 | C49: ='Tabulation Sheet'!C49 -> 0 | D49: ='Tabulation Sheet'!D49 -> 0 | E49: ='Tabulation Sheet'!E49 -> 0 | F49: ='Tabulation Sheet'!F49 -> 0
...

Sheet Report
J1: Document Code: | K1: FM-CSF-ACT-RPT
J2: Version No.: | K2: 0
J3: Effectivity Date: | K3: September 1, 2025
A6: CUSTOMER SATISFACTION FEEDBACK REPORT
A7: [Bureau/Office]
A8: For the period [Month, DD, YYYY]
A10: Process | H10: Total Responses | I10: =F47 -> 31
A11: Title of Activity: | H11: Total Number of Clients | I11: 35
H12: Retrieval Rate | I12: =I10/I11 -> 0.88571429
H13: Overall Satisfaction | I13: =J44+J45 -> 0.91904762
A14: I. Report Summary | H14: Adjectival Rating | I14: {=IF(I13=0,"N/A",_xlfn.IFS(I13>=0.95,"Outstanding",I13>=0.9,"Very Satisfactory",I13>=0.8,"Satisfactory",I13>=0.6,"Fair",I13<0.6,"Poor"))} -> Very Satisfactory
A17: Level of Satisfaction | B17: OVERALL SCORING | C17: Overall Rating/SQD 0 | D17: Responsiveness | E17: Reliability | F17: Access & Facilities | G17: Communication | H17: Costs | I17: Integrity | J17: Assurance | K17: Outcome
A18: Strongly Agree | B18: =SUM(D18:K18) -> 116 | C18: =COUNTIF('Tabulation Sheet'!$J$9:$J$1048576,"5") -> 30 | D18: =COUNTIF('Tabulation Sheet'!$K$9:$K$1048576,"5") -> 29 | E18: =COUNTIF('Tabulation Sheet'!$L$9:$L$1048576,"5") -> 16 | F18: =COUNTIF('Tabulation Sheet'!$M$9:$M$1048576,"5") -> 30 | G18: =COUNTIF('Tabulation Sheet'!$N$9:$N$1048576,"5") -> 11 | H18: =COUNTIF('Tabulation Sheet'!$O$9:$O$1048576,"5") -> 0 | I18: =COUNTIF('Tabulation Sheet'!$P$9:$P$1048576,"5") -> 0 | J18: =COUNTIF('Tabulation Sheet'!$Q$9:$Q$1048576,"5") -> 30 | K18: =COUNTIF('Tabulation Sheet'!$R$9:$R$1048576,"5") -> 0
A19: Agree | B19: =SUM(D19:K19) -> 77 | C19: =COUNTIF('Tabulation Sheet'!$J$9:$J$1048576,"4") -> 0 | D19: =COUNTIF('Tabulation Sheet'!$K$9:$K$1048576,"4") -> 0 | E19: =COUNTIF('Tabulation Sheet'!$L$9:$L$1048576,"4") -> 5 | F19: =COUNTIF('Tabulation Sheet'!$M$9:$M$1048576,"4") -> 0 | G19: =COUNTIF('Tabulation Sheet'!$N$9:$N$1048576,"4") -> 18 | H19: =COUNTIF('Tabulation Sheet'!$O$9:$O$1048576,"4") -> 0 | I19: =COUNTIF('Tabulation Sheet'!$P$9:$P$1048576,"4") -> 24 | J19: =COUNTIF('Tabulation Sheet'!$Q$9:$Q$1048576,"4") -> 0 | K19: =COUNTIF('Tabulation Sheet'!$R$9:$R$1048576,"4") -> 30
A20: Neither Agree nor Disagree | B20: =SUM(D20:K20) -> 16 | C20: =COUNTIF('Tabulation Sheet'!$J$9:$J$1048576,"3") -> 0 | D20: =COUNTIF('Tabulation Sheet'!$K$9:$K$1048576,"3") -> 0 | E20: =COUNTIF('Tabulation Sheet'!$L$9:$L$1048576,"3") -> 9 | F20: =COUNTIF('Tabulation Sheet'!$M$9:$M$1048576,"3") -> 0 | G20: =COUNTIF('Tabulation Sheet'!$N$9:$N$1048576,"3") -> 1 | H20: =COUNTIF('Tabulation Sheet'!$O$9:$O$1048576,"3") -> 0 | I20: =COUNTIF('Tabulation Sheet'!$P$9:$P$1048576,"3") -> 6 | J20: =COUNTIF('Tabulation Sheet'!$Q$9:$Q$1048576,"3") -> 0 | K20: =COUNTIF('Tabulation Sheet'!$R$9:$R$1048576,"3") -> 0
A21: Disagree | B21: =SUM(D21:K21) -> 1 | C21: =COUNTIF('Tabulation Sheet'!$J$9:$J$1048576,"2") -> 0 | D21: =COUNTIF('Tabulation Sheet'!$K$9:$K$1048576,"2") -> 1 | E21: =COUNTIF('Tabulation Sheet'!$L$9:$L$1048576,"2") -> 0 | F21: =COUNTIF('Tabulation Sheet'!$M$9:$M$1048576,"2") -> 0 | G21: =COUNTIF('Tabulation Sheet'!$N$9:$N$1048576,"2") -> 0 | H21: =COUNTIF('Tabulation Sheet'!$O$9:$O$1048576,"2") -> 0 | I21: =COUNTIF('Tabulation Sheet'!$P$9:$P$1048576,"2") -> 0 | J21: =COUNTIF('Tabulation Sheet'!$Q$9:$Q$1048576,"2") -> 0 | K21: =COUNTIF('Tabulation Sheet'!$R$9:$R$1048576,"2") -> 0
A22: Strongly Disagree | B22: =SUM(D22:K22) -> 0 | C22: =COUNTIF('Tabulation Sheet'!$J$9:$J$1048576,"1") -> 0 | D22: =COUNTIF('Tabulation Sheet'!$K$9:$K$1048576,"1") -> 0 | E22: =COUNTIF('Tabulation Sheet'!$L$9:$L$1048576,"1") -> 0 | F22: =COUNTIF('Tabulation Sheet'!$M$9:$M$1048576,"1") -> 0 | G22: =COUNTIF('Tabulation Sheet'!$N$9:$N$1048576,"1") -> 0 | H22: =COUNTIF('Tabulation Sheet'!$O$9:$O$1048576,"1") -> 0 | I22: =COUNTIF('Tabulation Sheet'!$P$9:$P$1048576,"1") -> 0 | J22: =COUNTIF('Tabulation Sheet'!$Q$9:$Q$1048576,"1") -> 0 | K22: =COUNTIF('Tabulation Sheet'!$R$9:$R$1048576,"1") -> 0
A23: Not Applicable | B23: =SUM(D23:K23) -> 38 | C23: =COUNTIF('Tabulation Sheet'!$J$9:$J$1048576,"-") -> 1 | D23: =COUNTIF('Tabulation Sheet'!$K$9:$K$1048576,"-") -> 1 | E23: =COUNTIF('Tabulation Sheet'!$L$9:$L$1048576,"-") -> 1 | F23: =COUNTIF('Tabulation Sheet'!$M$9:$M$1048576,"-") -> 1 | G23: =COUNTIF('Tabulation Sheet'!$N$9:$N$1048576,"-") -> 1 | H23: =COUNTIF('Tabulation Sheet'!$O$9:$O$1048576,"-") -> 31 | I23: =COUNTIF('Tabulation Sheet'!$P$9:$P$1048576,"-") -> 1 | J23: =COUNTIF('Tabulation Sheet'!$Q$9:$Q$1048576,"-") -> 1 | K23: =COUNTIF('Tabulation Sheet'!$R$9:$R$1048576,"-") -> 1
A24: TOTAL | B24: =SUM(B18:B23) -> 248 | C24: =SUM(C18:C23) -> 31 | D24: =SUM(D18:D23) -> 31 | E24: =SUM(E18:E23) -> 31 | F24: =SUM(F18:F23) -> 31 | G24: =SUM(G18:G23) -> 31 | H24: =SUM(H18:H23) -> 31 | I24: =SUM(I18:I23) -> 31 | ... K24: =SUM(K18:K23) -> 31
A25: CSF Rating | B25: =IFERROR(((B18+B19)/(B24-B23)),"0") -> 0.91904762 | C25: =IFERROR(((C18+C19)/(C24)),"0") -> 0.96774194 | D25: =IFERROR(((D18+D19)/(D24)),"0") -> 0.93548387 | E25: =IFERROR(((E18+E19)/(E24)),"0") -> 0.67741935 | F25: =IFERROR(((F18+F19)/(F24)),"0") -> 0.96774194 | G25: =IFERROR(((G18+G19)/(G24)),"0") -> 0.93548387 | H25: =IFERROR(((H18+H19)/(H24)),"0") -> 0 | I25: =IFERROR(((I18+I19)/(I24)),"0") -> 0.77419355 | J25: =IFERROR(((J18+J19)/(J24)),"0") -> 0.96774194 | K25: =IFERROR(((K18+K19)/(K24)),"0") -> 0.96774194
A26: Adjectival Rating | B26: {=IF(B25=0,"N/A",_xlfn.IFS(B25>=0.95,"Outstanding",B25>=0.9,"Very Satisfactory",B25>=0.8,"Satisfactory",B25>=0.6,"Fair",B25<0.6,"Poor"))} -> Very Satisfactory | C26: {=IF(C25=0,"N/A",_xlfn.IFS(C25>=0.95,"Outstanding",C25>=0.9,"Very Satisfactory",C25>=0.8,"Satisfactory",C25>=0.6,"Fair",C25<0.6,"Poor"))} -> Outstanding | D26: {=IF(D25=0,"N/A",_xlfn.IFS(D25>=0.95,"Outstanding",D25>=0.9,"Very Satisfactory",D25>=0.8,"Satisfactory",D25>=0.6,"Fair",D25<0.6,"Poor"))} -> Very Satisfactory | E26: {=IF(E25=0,"N/A",_xlfn.IFS(E25>=0.95,"Outstanding",E25>=0.9,"Very Satisfactory",E25>=0.8,"Satisfactory",E25>=0.6,"Fair",E25<0.6,"Poor"))} -> Fair | F26: {=IF(F25=0,"N/A",_xlfn.IFS(F25>=0.95,"Outstanding",F25>=0.9,"Very Satisfactory",F25>=0.8,"Satisfactory",F25>=0.6,"Fair",F25<0.6,"Poor"))} -> Outstanding | G26: {=IF(G25=0,"N/A",_xlfn.IFS(G25>=0.95,"Outstanding",G25>=0.9,"Very Satisfactory",G25>=0.8,"Satisfactory",G25>=0.6,"Fair",G25<0.6,"Poor"))} -> Very Satisfactory | H26: {=IF(H25=0,"N/A",_xlfn.IFS(H25>=0.95,"Outstanding",H25>=0.9,"Very Satisfactory",H25>=0.8,"Satisfactory",H25>=0.6,"Fair",H25<0.6,"Poor"))} -> N/A | I26: {=IF(I25=0,"N/A",_xlfn.IFS(I25>=0.95,"Outstanding",I25>=0.9,"Very Satisfactory",I25>=0.8,"Satisfactory",I25>=0.6,"Fair",I25<0.6,"Poor"))} -> Fair | ... K26: {=IF(K25=0,"N/A",_xlfn.IFS(K25>=0.95,"Outstanding",K25>=0.9,"Very Satisfactory",K25>=0.8,"Satisfactory",K25>=0.6,"Fair",K25<0.6,"Poor"))} -> Outstanding
A30: Level of Satisfaction | B30: Overall Scoring | C30: Speaker 1 | D30: Speaker 2 | E30: Speaker 3 | F30: Speaker 4 | G30: Speaker 5 | H30: Speaker 6 | I30: Speaker 7 | J30: Speaker 8
A31: Strongly Agree | B31: =SUM(C31:J31) -> 191 | C31: =COUNTIF(Supplemental!$G$9:$G$1048576,"5") -> 4 | D31: =COUNTIF(Supplemental!$H$9:$H$1048576,"5") -> 31 | E31: =COUNTIF(Supplemental!$I$9:$I$1048576,"5") -> 31 | F31: =COUNTIF(Supplemental!$J$9:$J$1048576,"5") -> 31 | G31: =COUNTIF(Supplemental!$K$9:$K$1048576,"5") -> 31 | H31: =COUNTIF(Supplemental!$L$9:$L$1048576,"5") -> 21 | I31: =COUNTIF(Supplemental!$M$9:$M$1048576,"5") -> 21 | J31: =COUNTIF(Supplemental!$N$9:$N$1048576,"5") -> 21
A32: Agree | B32: =SUM(C32:J32) -> 52 | C32: =COUNTIF(Supplemental!$G$9:$G$1048576,"4") -> 22 | D32: =COUNTIF(Supplemental!$H$9:$H$1048576,"4") -> 0 | E32: =COUNTIF(Supplemental!$I$9:$I$1048576,"4") -> 0 | F32: =COUNTIF(Supplemental!$J$9:$J$1048576,"4") -> 0 | G32: =COUNTIF(Supplemental!$K$9:$K$1048576,"4") -> 0 | H32: =COUNTIF(Supplemental!$L$9:$L$1048576,"4") -> 10 | I32: =COUNTIF(Supplemental!$M$9:$M$1048576,"4") -> 10 | J32: =COUNTIF(Supplemental!$N$9:$N$1048576,"4") -> 10
A33: Neither Agree nor Disagree | B33: =SUM(C33:J33) -> 4 | C33: =COUNTIF(Supplemental!$G$9:$G$1048576,"3") -> 4 | D33: =COUNTIF(Supplemental!$H$9:$H$1048576,"3") -> 0 | E33: =COUNTIF(Supplemental!$I$9:$I$1048576,"3") -> 0 | F33: =COUNTIF(Supplemental!$J$9:$J$1048576,"3") -> 0 | G33: =COUNTIF(Supplemental!$K$9:$K$1048576,"3") -> 0 | H33: =COUNTIF(Supplemental!$L$9:$L$1048576,"3") -> 0 | I33: =COUNTIF(Supplemental!$M$9:$M$1048576,"3") -> 0 | J33: =COUNTIF(Supplemental!$N$9:$N$1048576,"3") -> 0
A34: Disagree | B34: =SUM(C34:J34) -> 0 | C34: =COUNTIF(Supplemental!$G$9:$G$1048576,"2") -> 0 | D34: =COUNTIF(Supplemental!$H$9:$H$1048576,"2") -> 0 | E34: =COUNTIF(Supplemental!$I$9:$I$1048576,"2") -> 0 | F34: =COUNTIF(Supplemental!$J$9:$J$1048576,"2") -> 0 | G34: =COUNTIF(Supplemental!$K$9:$K$1048576,"2") -> 0 | H34: =COUNTIF(Supplemental!$L$9:$L$1048576,"2") -> 0 | I34: =COUNTIF(Supplemental!$M$9:$M$1048576,"2") -> 0 | J34: =COUNTIF(Supplemental!$N$9:$N$1048576,"2") -> 0
A35: Strongly Disagree | B35: =SUM(C35:J35) -> 0 | C35: =COUNTIF(Supplemental!$G$9:$G$1048576,"1") -> 0 | D35: =COUNTIF(Supplemental!$H$9:$H$1048576,"1") -> 0 | E35: =COUNTIF(Supplemental!$I$9:$I$1048576,"1") -> 0 | F35: =COUNTIF(Supplemental!$J$9:$J$1048576,"1") -> 0 | G35: =COUNTIF(Supplemental!$K$9:$K$1048576,"1") -> 0 | H35: =COUNTIF(Supplemental!$L$9:$L$1048576,"1") -> 0 | I35: =COUNTIF(Supplemental!$M$9:$M$1048576,"1") -> 0 | J35: =COUNTIF(Supplemental!$N$9:$N$1048576,"1") -> 0
A36: Not Applicable | B36: =SUM(C36:J36) -> 1 | C36: =COUNTIF(Supplemental!$G$9:$G$1048576,"-") -> 1 | D36: =COUNTIF(Supplemental!$H$9:$H$1048576,"-") -> 0 | E36: =COUNTIF(Supplemental!$I$9:$I$1048576,"-") -> 0 | F36: =COUNTIF(Supplemental!$J$9:$J$1048576,"-") -> 0 | G36: =COUNTIF(Supplemental!$K$9:$K$1048576,"-") -> 0 | H36: =COUNTIF(Supplemental!$L$9:$L$1048576,"-") -> 0 | I36: =COUNTIF(Supplemental!$M$9:$M$1048576,"-") -> 0 | J36: =COUNTIF(Supplemental!$N$9:$N$1048576,"-") -> 0
A37: TOTAL | B37: =SUM(B31:B36) -> 248 | C37: =SUM(C31:C36) -> 31 | D37: =SUM(D31:D36) -> 31 | E37: =SUM(E31:E36) -> 31 | F37: =SUM(F31:F36) -> 31 | G37: =SUM(G31:G36) -> 31 | H37: =SUM(H31:H36) -> 31 | I37: =SUM(I31:I36) -> 31 | J37: =SUM(J31:J36) -> 31
A38: CSF Rating | B38: =IFERROR(((B31+B32)/(B37-B36)),"0") -> 0.98380567 | C38: =IFERROR(((C31+C32)/(C37-C36)),"0") -> 0.86666667 | D38: =IFERROR(((D31+D32)/(D37-D36)),"0") -> 1 | E38: =IFERROR(((E31+E32)/(E37-E36)),"0") -> 1 | F38: =IFERROR(((F31+F32)/(F37-F36)),"0") -> 1 | G38: =IFERROR(((G31+G32)/(G37-G36)),"0") -> 1 | H38: =IFERROR(((H31+H32)/(H37-H36)),"0") -> 1 | I38: =IFERROR(((I31+I32)/(I37-I36)),"0") -> 1 | J38: =IFERROR(((J31+J32)/(J37-J36)),"0") -> 1
A39: Adjectival Rating | B39: {=IF(B38=0,"N/A",_xlfn.IFS(B38>=0.95,"Outstanding",B38>=0.9,"Very Satisfactory",B38>=0.8,"Satisfactory",B38>=0.6,"Fair",B38<0.6,"Poor"))} -> Outstanding | C39: {=IF(C38=0,"N/A",_xlfn.IFS(C38>=0.95,"Outstanding",C38>=0.9,"Very Satisfactory",C38>=0.8,"Satisfactory",C38>=0.6,"Fair",C38<0.6,"Poor"))} -> Satisfactory | D39: {=IF(D38=0,"N/A",_xlfn.IFS(D38>=0.95,"Outstanding",D38>=0.9,"Very Satisfactory",D38>=0.8,"Satisfactory",D38>=0.6,"Fair",D38<0.6,"Poor"))} -> Outstanding | E39: {=IF(E38=0,"N/A",_xlfn.IFS(E38>=0.95,"Outstanding",E38>=0.9,"Very Satisfactory",E38>=0.8,"Satisfactory",E38>=0.6,"Fair",E38<0.6,"Poor"))} -> Outstanding | F39: {=IF(F38=0,"N/A",_xlfn.IFS(F38>=0.95,"Outstanding",F38>=0.9,"Very Satisfactory",F38>=0.8,"Satisfactory",F38>=0.6,"Fair",F38<0.6,"Poor"))} -> Outstanding | G39: {=IF(G38=0,"N/A",_xlfn.IFS(G38>=0.95,"Outstanding",G38>=0.9,"Very Satisfactory",G38>=0.8,"Satisfactory",G38>=0.6,"Fair",G38<0.6,"Poor"))} -> Outstanding | H39: {=IF(H38=0,"N/A",_xlfn.IFS(H38>=0.95,"Outstanding",H38>=0.9,"Very Satisfactory",H38>=0.8,"Satisfactory",H38>=0.6,"Fair",H38<0.6,"Poor"))} -> Outstanding | I39: {=IF(I38=0,"N/A",_xlfn.IFS(I38>=0.95,"Outstanding",I38>=0.9,"Very Satisfactory",I38>=0.8,"Satisfactory",I38>=0.6,"Fair",I38<0.6,"Poor"))} -> Outstanding | J39: {=IF(J38=0,"N/A",_xlfn.IFS(J38>=0.95,"Outstanding",J38>=0.9,"Very Satisfactory",J38>=0.8,"Satisfactory",J38>=0.6,"Fair",J38<0.6,"Poor"))} -> Outstanding
A43: CC1 - Awareness of the Citizen's Charter | B43: # of Responses | C43: % Distribution | E43: Sex Disaggregation | F43: Count | G43: Distribution | I43: Level of Satisfaction | J43: Distribution | K43: Total
A44: (1) I know what a CC is and I saw this office’s CC. | B44: =COUNTIF(Tabulation_Frontline[CC1],"1") -> 30 | C44: =IFERROR(B44/B49, "-") -> 0.96774194 | E44: Male | F44: =COUNTIF('Tabulation Sheet'!$E$9:$E$1048576,"M") -> 17 | G44: =F44/F47 -> 0.5483871 | I44: Strongly Agree | J44: =B18/(B24-B23) -> 0.55238095 | K44: =SUM(J44:J48) -> 1
A45: (2) I know what a CC is but I did NOT see this office’s CC. | B45: =COUNTIF(Tabulation_Frontline[CC1],"2") -> 0 | C45: =B45/B49 -> 0 | E45: Female | F45: =COUNTIF('Tabulation Sheet'!$E$9:$E$1048576,"F") -> 13 | G45: =F45/F47 -> 0.41935484 | I45: Agree | J45: =B19/(B24-B23) -> 0.36666667
A46: (3) I learned of the CC only when I saw this office’s CC. | B46: =COUNTIF(Tabulation_Frontline[CC1],"3") -> 0 | C46: =B46/B49 -> 0 | E46: Did not specify | F46: =COUNTIF('Tabulation Sheet'!$E$9:$E$1048576,"Did not specify") -> 1 | G46: =F46/F47 -> 0.032258065 | I46: Neither Agree nor Disagree | J46: =B20/(B24-B23) -> 0.076190476
A47: (4) I do not know what a CC is and I did not see one in this office. | B47: =COUNTIF(Tabulation_Frontline[CC1],"4") -> 0 | C47: =B47/B49 -> 0 | E47: TOTAL | F47: =SUM(F44:F46) -> 31 | G47: =SUM(G44:G46) -> 1 | I47: Disagree | J47: =B21/(B24-B23) -> 0.0047619048
A48: (-) Not Applicable | B48: =COUNTIF(Tabulation_Frontline[CC1],"-") -> 1 | C48: =B48/B49 -> 0.032258065 | I48: Strongly Disagree | J48: =B22/(B24-B23) -> 0
A49: Total Responses | B49: =SUM(B44:B48) -> 31 | C49: =SUM(C44:C48) -> 1 | I49: Overall Satisfaction | J49: =J44+J45 -> 0.91904762
I50: Adjectival Rating | J50: {=IF(J49=0,"N/A",_xlfn.IFS(J49>=0.95,"Outstanding",J49>=0.9,"Very Satisfactory",J49>=0.8,"Satisfactory",J49>=0.6,"Fair",J49<0.6,"Poor"))} -> Very Satisfactory
A52: CC2 - Visibility of the Citizen's Charter | B52: # of Responses | C52: % Distribution | E52: Age | F52: Count | G52: Distribution
...

Sheet Graphs
B3: DEMOGRAPHIC PROFILE
B37: SERVICE QUALITY DIMENSIONS
